Workbook

Sheet Tri des prélèvements
A1: Prélèvement | B1: Nature | C1: Famille | D1: Assiette | E1: Sous-catégorie | F1: Ligne du schéma | G1: Sort | H1: Impôt absorbant | I1: Complément de | J1: Rendement 2026 (M€) | K1: Siège | L1: Statut du siège | M1: Fondement | N1: Observation
A2: TVA nette | B2: impôt ou taxe | C2: fiscal | D2: 6. La consommation | E2: Biens et services | F2: TVA | G2: conservé et absorbe | J2: 242838.2 | K2: 256 | L2: relevé par le fil, confirmé au dépôt | M2: M-028 — l'un des quatre impôts conservés
A3: Impôt net sur le revenu | B3: impôt ou taxe | C3: fiscal | D3: 4. Le revenu des personnes | E3: Traitements, salaires et pensions | F3: IR net | G3: conservé et absorbe | J3: 130178 | K3: 1 A | L3: relevé par le fil, confirmé au dépôt | M3: M-028 — l'un des quatre impôts conservés
A4: Impôt sur les sociétés | B4: impôt ou taxe | C4: fiscal | D4: 5. L'activité des entreprises | E4: Bénéfice des entreprises | F4: IS net | G4: conservé et absorbe | J4: 84694.4 | K4: 205 | L4: relevé par le fil, confirmé au dépôt | M4: M-028 — l'un des quatre impôts conservés
A5: Taxe foncière sur les propriétés bâties | B5: impôt ou taxe | C5: fiscal | D5: 7. La propriété et les droits d'usage | E5: Détention immobilière | F5: Taxe foncière | G5: conservé et absorbe | K5: 1380 | L5: relevé par le fil, confirmé au dépôt | M5: M-028 — l'un des quatre impôts conservés
A6: Retenues à la source et prélèvements sur les revenus de capitaux mobiliers et le prélèvement sur les bons anonymes | B6: impôt ou taxe | C6: fiscal | D6: 4. Le revenu des personnes | E6: Revenus du capital | F6: IR net | G6: fondu par rattachement | H6: Impôt sur le revenu | J6: 4800 | K6: 119 bis | L6: relevé par le fil, confirmé au dépôt | M6: M-028 et M-034 — assiette de revenu ou de plus-value ; un seul impôt sur le revenu
A7: Taxe sur les transactions financières - fraction affectée de la ressource État | B7: impôt ou taxe | C7: fiscal | D7: 4. Le revenu des personnes | E7: Revenus du capital | F7: IR net | G7: fondu par rattachement | H7: Impôt sur le revenu | J7: 2630 | K7: 235 ter ZD | L7: confirmé | M7: M-028 et M-034 — assiette de revenu ou de plus-value ; un seul impôt sur le revenu
A8: Autres impôts directs perçus par voie d'émission de rôles | B8: impôt ou taxe | C8: fiscal | D8: 4. Le revenu des personnes | E8: Traitements, salaires et pensions | F8: IR net | G8: fondu par rattachement | H8: Impôt sur le revenu | J8: 2414.3 | L8: non établi | M8: M-028 et M-034 — assiette de revenu ou de plus-value ; un seul impôt sur le revenu | N8: reclassé le 20261015 : impôt principal renseigné
A9: CDHR | B9: impôt ou taxe | C9: fiscal | D9: 4. Le revenu des personnes | E9: Traitements, salaires et pensions | F9: IR net | G9: fondu par rattachement | H9: Impôt sur le revenu | J9: 1650 | K9: 224 | L9: relevé par le fil, confirmé au dépôt | M9: M-028 et M-034 — assiette de revenu ou de plus-value ; un seul impôt sur le revenu
A10: Retenues à la source sur certains bénéfices non commerciaux et de l'impôt sur le revenu | B10: impôt ou taxe | C10: fiscal | D10: 4. Le revenu des personnes | E10: Traitements, salaires et pensions | F10: IR net | G10: fondu par rattachement | H10: Impôt sur le revenu | J10: 1127.9 | K10: 182 B | L10: relevé par le fil, confirmé au dépôt | M10: M-028 et M-034 — assiette de revenu ou de plus-value ; un seul impôt sur le revenu
A11: Taxe sur la cession à titre onéreux des terrains nus ou des droits relatifs à des terrains nus rendus constructibles du fait de leur classement | B11: impôt ou taxe | C11: fiscal | D11: 4. Le revenu des personnes | E11: Plus-values des particuliers | F11: IR net | G11: fondu par rattachement | H11: Impôt sur le revenu | J11: 17 | K11: 1605 nonies | L11: confirmé | M11: M-028 et M-034 — assiette de revenu ou de plus-value ; un seul impôt sur le revenu
A12: Contribution annuelle sur les revenus locatifs | B12: impôt ou taxe | C12: fiscal | D12: 4. Le revenu des personnes | E12: Revenus fonciers | F12: IR net | G12: fondu par rattachement | H12: Impôt sur le revenu | K12: 234 nonies | L12: relevé par le fil, confirmé au dépôt | M12: M-028 et M-034 — assiette de revenu ou de plus-value ; un seul impôt sur le revenu
A13: Exit tax | B13: impôt ou taxe | C13: fiscal | D13: 4. Le revenu des personnes | E13: Plus-values des particuliers | F13: IR net | G13: fondu par rattachement | H13: Impôt sur le revenu | K13: 167 bis | L13: relevé par le fil, confirmé au dépôt | M13: M-028 et M-034 — assiette de revenu ou de plus-value ; un seul impôt sur le revenu
A14: Taxe spéciale due en cas de non-respect de l'engagement de conserver pendant 5 ans les parts de FCPR ou FCPI | B14: impôt ou taxe | C14: fiscal | D14: 4. Le revenu des personnes | E14: Revenus du capital | F14: IR net | G14: fondu par rattachement | H14: Impôt sur le revenu | L14: non établi | M14: M-028 et M-034 — assiette de revenu ou de plus-value ; un seul impôt sur le revenu
A15: Taxe sur les ordres annulés dans le cadre d'opérations à haute fréquence | B15: impôt ou taxe | C15: fiscal | D15: 4. Le revenu des personnes | E15: Revenus du capital | F15: IR net | G15: fondu par rattachement | H15: Impôt sur le revenu | K15: 235 ter ZD bis | L15: relevé par le fil, confirmé au dépôt | M15: M-028 et M-034 — assiette de revenu ou de plus-value ; un seul impôt sur le revenu
A16: Taxe sur les plus-values immobilières (PVI) autres que terrains à bâtir | B16: impôt ou taxe | C16: fiscal | D16: 4. Le revenu des personnes | E16: Plus-values des particuliers | F16: IR net | G16: fondu par rattachement | H16: Impôt sur le revenu | K16: 1609 nonies G | L16: relevé par le fil, confirmé au dépôt | M16: M-028 et M-034 — assiette de revenu ou de plus-value ; un seul impôt sur le revenu
A17: Contribution sociale de solidarité des sociétés (C3S) | B17: impôt ou taxe | C17: fiscal | D17: 5. L'activité des entreprises | E17: Bénéfice des entreprises | F17: Taxes sur chiffre d'affaires et bénéfices | G17: fondu par rattachement | H17: Impôt sur les sociétés | J17: 5452.3 | K17: L137-30 | L17: confirmé | M17: M-028 — assiette de bénéfice ; elle revient à l'impôt sur les sociétés
A18: Contribution exceptionnelle sur les bénéfices des entreprises | B18: impôt ou taxe | C18: fiscal | D18: 5. L'activité des entreprises | E18: Bénéfice des entreprises | F18: Taxes sur chiffre d'affaires et bénéfices | G18: fondu par rattachement | H18: Impôt sur les sociétés | J18: 4000 | L18: non établi | M18: M-028 — assiette de bénéfice ; elle revient à l'impôt sur les sociétés
A19: CVAE | B19: impôt ou taxe | C19: fiscal | D19: 5. L'activité des entreprises | E19: Valeur ajoutée | F19: Autres taxes sur les entreprises | G19: fondu par rattachement | H19: Impôt sur les sociétés | J19: 2741.3 | K19: 1586 ter | L19: relevé par le fil, confirmé au dépôt | M19: M-031 — impôt de production ; schéma : ligne supprimée en totalité (−13,5 sur 13,2)
A20: Contribution sociale nette sur les bénéfices des sociétés | B20: impôt ou taxe | C20: fiscal | D20: 5. L'activité des entreprises | E20: Bénéfice des entreprises | F20: Taxes sur chiffre d'affaires et bénéfices | G20: fondu par rattachement | H20: Impôt sur les sociétés | J20: 1411 | K20: 235 ter ZC | L20: relevé par le fil, confirmé au dépôt | M20: M-028 — assiette de bénéfice ; elle revient à l'impôt sur les sociétés
A21: Taxe générale sur les activités polluantes | B21: impôt ou taxe | C21: fiscal | D21: 5. L'activité des entreprises | E21: Autres prélèvements sur les entreprises | F21: dont taxe pollution | G21: fondu par rattachement | H21: Impôt sur les sociétés | J21: 1356 | K21: 266 sexies | L21: relevé par le fil, confirmé au dépôt | M21: M-030 — taxe spécifique sur un produit ou un service particulier ; schéma : ligne supprimée en totalité
A22: Taxes annuelles sur les émissions de CO2 et les émissions de polluants des véhicules de tourisme affectés à une activité économique (TAVTAE - CO2 et TAVTAE - polluants) | B22: impôt ou taxe | C22: fiscal | D22: 5. L'activité des entreprises | E22: Autres prélèvements sur les entreprises | F22: dont véhicules | G22: fondu par rattachement | H22: Impôt sur les sociétés | J22: 1210 | K22: L421-93 | L22: confirmé | M22: M-030 — taxe spécifique sur un produit ou un service particulier ; schéma : ligne supprimée en totalité
A23: Taxe sur les installations nucléaires de base relevant du secteur énergétique et assimilées, tarif de base (TINB-E, TA) | B23: impôt ou taxe | C23: fiscal | D23: 5. L'activité des entreprises | E23: Équipements, installations et réseaux | F23: Autres taxes sur les entreprises | G23: fondu par rattachement | H23: Impôt sur les sociétés | J23: 793.2 | K23: L322-39 | L23: confirmé | M23: M-031 — impôt de production ; schéma : ligne supprimée en totalité (−13,5 sur 13,2)
A24: Taxe sur l'exploitation des infrastructures de transport de longue distance (TEITLD) | B24: impôt ou taxe | C24: fiscal | D24: 5. L'activité des entreprises | E24: Chiffre d'affaires | F24: Taxes sur chiffre d'affaires et bénéfices | G24: fondu par rattachement | H24: Impôt sur les sociétés | J24: 700 | K24: L425-1 | L24: confirmé | M24: M-031 — impôt de production assis sur le chiffre d'affaires ou les dépenses
A25: Contribution sur le chiffre d'affaires des entreprises exploitant une ou plusieurs spécialités pharmaceutiques | B25: impôt ou taxe | C25: fiscal | D25: 5. L'activité des entreprises | E25: Chiffre d'affaires | F25: Taxes sur chiffre d'affaires et bénéfices | G25: fondu par rattachement | H25: Impôt sur les sociétés | J25: 658.9 | K25: L245-6 | L25: confirmé | M25: M-031 — impôt de production assis sur le chiffre d'affaires ou les dépenses
A26: Cotisation versée par les organismes HLM et les SEM | B26: impôt ou taxe | C26: fiscal | D26: 5. L'activité des entreprises | E26: Bailleurs sociaux | F26: Autres taxes sur les entreprises | G26: fondu par rattachement | H26: Impôt sur les sociétés | J26: 590.2 | K26: L452-4 | L26: confirmé | M26: M-031 — impôt de production ; schéma : ligne supprimée en totalité (−13,5 sur 13,2)
A27: Transposition de la directive UE sur la taxation minimale des multinationales | B27: impôt ou taxe | C27: fiscal | D27: 5. L'activité des entreprises | E27: Bénéfice des entreprises | F27: Taxes sur chiffre d'affaires et bénéfices | G27: fondu par rattachement | H27: Impôt sur les sociétés | J27: 500 | K27: 223 VJ | L27: relevé par le fil, confirmé au dépôt | M27: M-028 — assiette de bénéfice ; elle revient à l'impôt sur les sociétés
A28: Imposition forfaitaire annuelle sur les pylônes | B28: impôt ou taxe | C28: fiscal | D28: 5. L'activité des entreprises | E28: Équipements, installations et réseaux | F28: Autres taxes sur les entreprises | G28: fondu par rattachement | H28: Impôt sur les sociétés | J28: 376.8 | K28: 1519 A | L28: confirmé | M28: M-031 — impôt de production ; schéma : ligne supprimée en totalité (−13,5 sur 13,2)
A29: Contribution de la Caisse des dépôts et consignations représentative de l'impôt sur les sociétés | B29: impôt ou taxe | C29: fiscal | D29: 5. L'activité des entreprises | E29: Bénéfice des entreprises | F29: Taxes sur chiffre d'affaires et bénéfices | G29: fondu par rattachement | H29: Impôt sur les sociétés | J29: 374 | L29: non établi | M29: M-028 — assiette de bénéfice ; elle revient à l'impôt sur les sociétés
A30: TA-CVAE - Taxe additionnelle à la cotisation sur la valeur ajoutée des entreprises pour frais de chambres de commerce et d'industrie de région | B30: impôt ou taxe | C30: fiscal | D30: 5. L'activité des entreprises | E30: Valeur ajoutée | F30: Autres taxes sur les entreprises | G30: fondu par rattachement | H30: Impôt sur les sociétés | J30: 326.3 | L30: non établi | M30: M-031 — impôt de production ; schéma : ligne supprimée en totalité (−13,5 sur 13,2)
A31: Contribution due par les laboratoires et les grossistes répartiteurs sur les ventes en gros aux officines pharmaceutiques | B31: impôt ou taxe | C31: fiscal | D31: 5. L'activité des entreprises | E31: Chiffre d'affaires | F31: Taxes sur chiffre d'affaires et bénéfices | G31: fondu par rattachement | H31: Impôt sur les sociétés | J31: 271.1 | K31: L138-1 | L31: confirmé | M31: M-031 — impôt de production assis sur le chiffre d'affaires ou les dépenses
A32: Taxe sur les rachats d'actions | B32: impôt ou taxe | C32: fiscal | D32: 5. L'activité des entreprises | E32: Bénéfice des entreprises | F32: Taxes sur chiffre d'affaires et bénéfices | G32: fondu par rattachement | H32: Impôt sur les sociétés | J32: 200 | L32: non établi | M32: M-028 — assiette de bénéfice ; elle revient à l'impôt sur les sociétés
A33: Taxe spéciale sur certains véhicules routiers | B33: impôt ou taxe | C33: fiscal | D33: 5. L'activité des entreprises | E33: Autres prélèvements sur les entreprises | F33: dont véhicules | G33: fondu par rattachement | H33: Impôt sur les sociétés | J33: 176.5 | L33: non établi | M33: M-030 — taxe spécifique sur un produit ou un service particulier ; schéma : ligne supprimée en totalité
A34: Taxe sur les installations nucléaires de base relevant du secteur énergétique et assimilées, tarif de conception (TINB-E, TC) | B34: impôt ou taxe | C34: fiscal | D34: 5. L'activité des entreprises | E34: Équipements, installations et réseaux | F34: Autres taxes sur les entreprises | G34: fondu par rattachement | H34: Impôt sur les sociétés | J34: 133.3 | K34: L322-39 | L34: confirmé | M34: M-031 — impôt de production ; schéma : ligne supprimée en totalité (−13,5 sur 13,2)
A35: Contribution due par les laboratoires sur leurs dépenses de publicité | B35: impôt ou taxe | C35: fiscal | D35: 5. L'activité des entreprises | E35: Dépenses des entreprises | F35: Autres taxes sur les entreprises | G35: fondu par rattachement | H35: Impôt sur les sociétés | J35: 129.9 | K35: L245-1 | L35: confirmé | M35: M-031 — impôt de production ; schéma : ligne supprimée en totalité (−13,5 sur 13,2)
A36: Imposition forfaitaire sur le matériel roulant circulant sur le réseau de transport ferroviaire et guidé géré par la RATP - IFER-STIF RATP | B36: impôt ou taxe | C36: fiscal | D36: 5. L'activité des entreprises | E36: Équipements, installations et réseaux | F36: Autres taxes sur les entreprises | G36: fondu par rattachement | H36: Impôt sur les sociétés | J36: 86.2 | K36: 1599 quater A bis | L36: confirmé | M36: M-031 — impôt de production ; schéma : ligne supprimée en totalité (−13,5 sur 13,2)
A37: Taxe sur les installations nucléaires de base relevant du secteur énergétique et assimilées, tarif de recherche (TINB-E, TR) | B37: impôt ou taxe | C37: fiscal | D37: 5. L'activité des entreprises | E37: Équipements, installations et réseaux | F37: Autres taxes sur les entreprises | G37: fondu par rattachement | H37: Impôt sur les sociétés | J37: 63.2 | K37: L322-39 | L37: confirmé | M37: M-031 — impôt de production ; schéma : ligne supprimée en totalité (−13,5 sur 13,2)
A38: Taxe sur les installations nucléaires de base relevant du secteur énergétique et assimilées, tarif d'accompagnement (TINB-E, TA) | B38: impôt ou taxe | C38: fiscal | D38: 5. L'activité des entreprises | E38: Équipements, installations et réseaux | F38: Autres taxes sur les entreprises | G38: fondu par rattachement | H38: Impôt sur les sociétés | J38: 57.9 | K38: L322-39 | L38: confirmé | M38: M-031 — impôt de production ; schéma : ligne supprimée en totalité (−13,5 sur 13,2)
A39: Contribution due par les entreprises fabriquant ou exploitant des dispositifs médicaux sur leurs dépenses de publicité | B39: impôt ou taxe | C39: fiscal | D39: 5. L'activité des entreprises | E39: Chiffre d'affaires | F39: Taxes sur chiffre d'affaires et bénéfices | G39: fondu par rattachement | H39: Impôt sur les sociétés | J39: 48.2 | K39: L245-5-1 | L39: confirmé | M39: M-031 — impôt de production assis sur le chiffre d'affaires ou les dépenses
A40: Cotisation additionnelle versée par les organismes HLM et les SEM | B40: impôt ou taxe | C40: fiscal | D40: 5. L'activité des entreprises | E40: Bailleurs sociaux | F40: Autres taxes sur les entreprises | G40: fondu par rattachement | H40: Impôt sur les sociétés | J40: 38 | K40: L452-4-1 | L40: confirmé | M40: M-031 — impôt de production ; schéma : ligne supprimée en totalité (−13,5 sur 13,2)
...

Sheet Synthèse par sort
A1: TRI DES PRÉLÈVEMENTS OBLIGATOIRES — SYNTHÈSE PAR SORT
A2: Vocabulaire du schéma « Refonte fiscalité ». Aucun prélèvement ne disparaît sans contrepartie : son produit est repris, soit par l’impôt qui l’absorbe, soit par les hausses d’équilibre des quatre impôts conservés.
A4: Sort | B4: Nombre | C4: Rendement 2026 (M€) | D4: Part
A5: conservé et absorbe | B5: =COUNTIF('Tri des prélèvements'!$G$2:$G$421,A5) -> 4 | C5: =SUMIF('Tri des prélèvements'!$G$2:$G$421,A5,'Tri des prélèvements'!$J$2:$J$421) -> 457710.6 | D5: =IFERROR(C5/$C$10,0) -> 0.52205426
A6: fondu par rattachement | B6: =COUNTIF('Tri des prélèvements'!$G$2:$G$421,A6) -> 258 | C6: =SUMIF('Tri des prélèvements'!$G$2:$G$421,A6,'Tri des prélèvements'!$J$2:$J$421) -> 310765.1 | D6: =IFERROR(C6/$C$10,0) -> 0.35445158
A7: fondu dans l’équilibre | B7: =COUNTIF('Tri des prélèvements'!$G$2:$G$421,A7) -> 112 | C7: =SUMIF('Tri des prélèvements'!$G$2:$G$421,A7,'Tri des prélèvements'!$J$2:$J$421) -> 43963.4 | D7: =IFERROR(C7/$C$10,0) -> 0.05014365
A8: maintenu à part | B8: =COUNTIF('Tri des prélèvements'!$G$2:$G$421,A8) -> 43 | C8: =SUMIF('Tri des prélèvements'!$G$2:$G$421,A8,'Tri des prélèvements'!$J$2:$J$421) -> 62649.3 | D8: =IFERROR(C8/$C$10,0) -> 0.071456361
A9: hors champ | B9: =COUNTIF('Tri des prélèvements'!$G$2:$G$421,A9) -> 3 | C9: =SUMIF('Tri des prélèvements'!$G$2:$G$421,A9,'Tri des prélèvements'!$J$2:$J$421) -> 1660.7 | D9: =IFERROR(C9/$C$10,0) -> 0.0018941565
A10: Total | B10: =SUM(B5:B9) -> 420 | C10: =SUM(C5:C9) -> 876749.1
A12: Source : chantier/referentiels/prelevements_forces_20260930.tsv, colonne rang, et onglet « Refonte fiscalité » de Synthèse Calculs Résolution.
A13: 65 rangs reclassés le 15 octobre 2026 : classés non rattachables alors qu’ils portaient un impôt principal.
A14: 21 rangs reclassés en maintenu à part : lignes du schéma sans valeur en colonne « Taxes à supprimer » — assurances, taxe de séjour, outre-mer, forfaits de cotisation.
A15: 188 rangs sur 420 n’ont pas de rendement 2026 isolé à la source. Un rendement vide ne vaut pas zéro.

Sheet Synthèse par nature
A1: TRI DES PRÉLÈVEMENTS — SYNTHÈSE PAR NATURE
A2: Les cotisations et les contributions sociales sont suivies à part de bout en bout. Elles sont un prélèvement comme un autre, et le tri les traite comme tel sans cesser de les distinguer.
A4: Nature | B4: Nombre | C4: Rendement 2026 (M€) | D4: Part
A5: impôt ou taxe | B5: =COUNTIF('Tri des prélèvements'!$B$2:$B$421,A5) -> 288 | C5: =SUMIF('Tri des prélèvements'!$B$2:$B$421,A5,'Tri des prélèvements'!$J$2:$J$421) -> 638772.3 | D5: =IFERROR(C5/$C$10,0) -> 0.7285691
A6: cotisation sociale | B6: =COUNTIF('Tri des prélèvements'!$B$2:$B$421,A6) -> 83 | C6: =SUMIF('Tri des prélèvements'!$B$2:$B$421,A6,'Tri des prélèvements'!$J$2:$J$421) -> 2212.8 | D6: =IFERROR(C6/$C$10,0) -> 0.0025238691
A7: contribution sociale | B7: =COUNTIF('Tri des prélèvements'!$B$2:$B$421,A7) -> 16 | C7: =SUMIF('Tri des prélèvements'!$B$2:$B$421,A7,'Tri des prélèvements'!$J$2:$J$421) -> 192352.7 | D7: =IFERROR(C7/$C$10,0) -> 0.2193931
A8: taxe sur la masse salariale | B8: =COUNTIF('Tri des prélèvements'!$B$2:$B$421,A8) -> 30 | C8: =SUMIF('Tri des prélèvements'!$B$2:$B$421,A8,'Tri des prélèvements'!$J$2:$J$421) -> 41750.6 | D8: =IFERROR(C8/$C$10,0) -> 0.047619781
A9: hors champ | B9: =COUNTIF('Tri des prélèvements'!$B$2:$B$421,A9) -> 3 | C9: =SUMIF('Tri des prélèvements'!$B$2:$B$421,A9,'Tri des prélèvements'!$J$2:$J$421) -> 1660.7 | D9: =IFERROR(C9/$C$10,0) -> 0.0018941565
A10: Total | B10: =SUM(B5:B9) -> 420 | C10: =SUM(C5:C9) -> 876749.1
A12: Les trois premières assiettes du tri — cotisations sociales, contributions sociales sur les revenus, taxes sur la masse salariale — forment la famille « prélèvement social », 129 rangs.

Sheet Synthèse par impôt absorbant
A1: Impôt absorbant | B1: Prélèvements fondus | C1: Rendement repris 2026 (M€)
A2: Taxe sur la valeur ajoutée | B2: =COUNTIF('Tri des prélèvements'!$H$2:$H$421,A2) -> 66 | C2: =SUMIF('Tri des prélèvements'!$H$2:$H$421,A2,'Tri des prélèvements'!$J$2:$J$421) -> 27822.9
A3: Impôt sur le revenu | B3: =COUNTIF('Tri des prélèvements'!$H$2:$H$421,A3) -> 26 | C3: =SUMIF('Tri des prélèvements'!$H$2:$H$421,A3,'Tri des prélèvements'!$J$2:$J$421) -> 195738.5
A4: Impôt sur les sociétés | B4: =COUNTIF('Tri des prélèvements'!$H$2:$H$421,A4) -> 50 | C4: =SUMIF('Tri des prélèvements'!$H$2:$H$421,A4,'Tri des prélèvements'!$J$2:$J$421) -> 21757.5
A5: Taxe foncière | B5: =COUNTIF('Tri des prélèvements'!$H$2:$H$421,A5) -> 116 | C5: =SUMIF('Tri des prélèvements'!$H$2:$H$421,A5,'Tri des prélèvements'!$J$2:$J$421) -> 65446.2
A6: Total fondu par rattachement | B6: =SUM(B2:B5) -> 258 | C6: =SUM(C2:C5) -> 310765.1
A8: Les prélèvements fondus dans l’équilibre ne portent pas d’impôt absorbant : leur produit est repris par les hausses d’équilibre des quatre impôts conservés.

Sheet Maintenus à part
A1: LES PRÉLÈVEMENTS MAINTENUS À PART
A2: Un prélèvement maintenu à part n’est pas conservé pour lui-même : il demeure comme complément de l’impôt qu’il prolonge, parce que le schéma ne lui assigne aucune suppression.
A4: Catégorie maintenue | B4: Rangs | C4: Rendement 2026 (M€) | D4: Complément de
A5: dont alcool, tabac, jeux | B5: 12 | C5: 16204.9 | D5: Taxe sur la valeur ajoutée
A6: dont assurances | B6: 8 | C6: 13548.2 | D6: Taxe sur la valeur ajoutée
A7: dont forfaits de cotisation | B7: 2 | C7: 9253.4 | D7: —
A8: dont outre-mer | B8: 3 | C8: 1744 | D8: Taxe sur la valeur ajoutée
A9: dont taxe de séjour | B9: 8 | C9: 1346.2 | D9: Taxe sur la valeur ajoutée
A10: dont énergie* | B10: 10 | C10: 20552.6 | D10: Taxe sur la valeur ajoutée
A11: Total | B11: =SUM(B5:B10) -> 43 | C11: =SUM(C5:C10) -> 62649.3

Sheet Ce qui reste à lever
A1: Point | B1: Mesure au 15 octobre 2026 | C1: État
A2: Rangs sans rendement 2026 | B2: 188 sur 420, soit 45 % | C2: ouvert
A3: Sièges juridiques non établis | B3: 105 sur 420, soit un quart | C3: ouvert
A4: Écart au manifeste | B4: 420 rangs relevés contre 438 affichés | C4: ouvert, non expliqué
A5: Rapprochement avec les liasses | B5: aucune colonne ne relie un rang à l’amendement qui le porte | C5: ouvert
A6: Contradictions rang / impôt principal | B6: 65 | C6: levé le 15 octobre 2026
A7: Catégories maintenues manquantes | B7: 21 rangs, quatre lignes du schéma | C7: levé le 15 octobre 2026
A8: Vocabulaire « supprimé » | B8: retiré, remplacé par les deux formes de fusion | C8: levé le 15 octobre 2026

Sheet Compteur trimestriel
A1: COMPTEUR TRIMESTRIEL DE LA RESTITUTION | H1: Paramètres
A2: Contribution sociale généralisée et contribution pour le remboursement de la dette sociale sur les revenus d’activité. Six marches mensuelles, de juillet à décembre 2027. Le premier semestre 2027 est celui de la mise en place : aucun taux ne bouge. | H2: Restitution en année pleine (Md€) | I2: 114.46
H3: Taux total avant réforme (points) | I3: 9.7
A4: Trimestre | B4: Mois | C4: Taux total CSG+CRDS (points) | D4: Restitué dans le mois (Md€) | E4: Restitué dans le trimestre (Md€) | H4: Restitué par point et par mois (Md€) | I4: =I2/I3/12 -> 0.98333333
A5: T1 2027 | B5: janvier à juin | C5: 9.7 | D5: 0 | E5: 0
A6: T2 2027 | C6: 9.7 | D6: 0 | E6: 0
A7: T3 2027 | B7: juillet | C7: 8.1 | D7: =($I$3-C7)*$I$4 -> 1.5733333 | E7: =SUM(D7:D9) -> 9.5383333
B8: août | C8: 6.5 | D8: =($I$3-C8)*$I$4 -> 3.1466667
B9: septembre | C9: 4.8 | D9: =($I$3-C9)*$I$4 -> 4.8183333
A10: T4 2027 | B10: octobre | C10: 3.2 | D10: =($I$3-C10)*$I$4 -> 6.3916667 | E10: =SUM(D10:D12) -> 23.895
B11: novembre | C11: 1.6 | D11: =($I$3-C11)*$I$4 -> 7.965
B12: décembre | C12: 0 | D12: =($I$3-C12)*$I$4 -> 9.5383333
A13: Total 2027 | D13: =SUM(D5:D12) -> 33.433333 | E13: =E7+E10 -> 33.433333
A14: Chaque trimestre de 2028 et au-delà | D14: =$I$2/4 -> 28.615
A16: L’exposé de l’amendement n° 1 du financement annonce 33,38 Md€ en 2027 et 114,46 Md€ en année pleine dès 2028. L’écart de 0,05 vient de l’arrondi des taux mensuels.
A17: Au 1er décembre 2027 les deux contributions cessent d’être dues sur ce qui rémunère un travail. La rémunération nette a monté de treize pour cent.

Sheet Compteur par agent
A1: COMPTEUR PAR AGENT ÉCONOMIQUE
A2: Qui porte l’effort, et vers qui il va. Chaque mesure d’économie est un transfert : le schéma des flux le nomme ligne par ligne. Le bénéficiaire est partout le même — les actifs.
A4: Agent économique qui porte l’effort | B4: Mesures | C4: Gain année 1 (Md€) | D4: Gain supplémentaire à terme (Md€) | E4: Total à terme (Md€)
A5: Consommateurs et secteurs soutenus | B5: Taux réduits de TVA · autres impôts et taxes | C5: 15.1 | D5: 14.1 | E5: 29.2
A6: Inactifs et revenus exonérés | B6: Impôt sur le revenu · niches sociales | C6: 28.8 | D6: 16.2 | E6: 45
A7: Secteurs soutenus par l’impôt | B7: Impôt sur les sociétés | C7: 8.2 | D7: 7.8 | E7: 16
A8: Secteurs subventionnés | B8: Aides aux entreprises, État et collectivités · opérateurs | C8: 32.6 | D8: 22.9 | E8: 55.5
A9: Secteurs associatifs et populations cibles | B9: Subventions aux associations · dépenses culturelles | C9: 19.6 | D9: 4.6 | E9: 24.2
A10: Bas revenus | B10: Chèques aux ménages | C10: 8.4 | D10: 11.5 | E10: 19.9
A11: Titulaires de marchés publics | B11: Charges courantes et achats, État et collectivités | C11: 9.9 | D11: 3.5 | E11: 13.4
A12: Agents publics, compensés à 70 % | B12: Départs de fonctionnaires, État et collectivités | C12: 6.9 | D12: 16.1 | E12: 23
A13: Total | C13: =SUM(C5:C12) -> 129.5 | D13: =SUM(D5:D12) -> 96.7 | E13: =SUM(E5:E12) -> 226.2
A15: Source : onglet « Flux » de Synthèse Calculs Résolution, colonnes « Gain année 1 », « Gain supp. à terme » et « Total supprimé à terme », regroupées selon la colonne « Effets » qui nomme le transfert.
A16: Le schéma des flux annonce 129,4 Md€ en année 1, 96,7 Md€ de gain supplémentaire à terme et 226,2 Md€ au total, plus 97 Md€ d’autre gisement.
A17: Les quatre lignes de niches fiscales du schéma des flux sont réparties ici entre les agents qui en bénéficiaient ; les économies de l’État et des collectivités le sont entre leurs bénéficiaires.
